Workbook

Sheet Copy of Sunbird ED Execution Da
A1: Sunbird ED Regression Dashboard
A2: ED Component | B2: Portal/Mobile/Desktop app | C2: Total | E2: Not Applicable | G2: To be Executed | I2: Passed | K2: Fail | M2: Blocked | O2: For retest (Failed & Blocked) | Q2: Execution % circle wise
C3: P1 | D3: P2 | E3: P1 | F3: P2 | G3: P1 | H3: P2 | I3: P1 | J3: P2 | K3: P1 | L3: P2 | M3: P1 | N3: P2 | O3: P1 | P3: P2 | Q3: P1 | R3: P2
A4: Sanity | B4: Portal | C4: =COUNTA('Portal Sanity'!D2:D1005) -> 110 | D4: 0 | E4: =COUNTIF('Portal Sanity'!K2:K1005,"NA") -> 2 | F4: 0 | G4: =C4-(I4+O4+E4) -> 0 | H4: 0 | I4: =COUNTIF('Portal Sanity'!K2:K1005,"Pass") -> 108 | J4: 0 | K4: =COUNTIF('Portal Sanity'!K2:K1005,"Fail") -> 0 | L4: 0 | M4: =COUNTIF('Portal Sanity'!K2:K1005,"Blocked") -> 0 | N4: 0 | O4: =SUM(K4+M4) -> 0 | P4: 0 | Q4: =(E4+I4)/C4 -> 1 | R4: 0
B5: Mobile | C5: =COUNTA('Mobile Sanity'!D2:D1005) -> 111 | D5: 0 | E5: =COUNTIF('Mobile Sanity'!K2:K1005,"NA") -> 4 | F5: 0 | G5: =C5-(I5+O5+E5) -> 0 | H5: 0 | I5: =COUNTIF('Mobile Sanity'!K2:K1005,"Pass") -> 107 | J5: 0 | K5: =COUNTIF('Mobile Sanity'!K2:K1005,"Fail") -> 0 | L5: 0 | M5: =COUNTIF('Mobile Sanity'!K2:K1005,"Blocked") -> 0 | N5: 0 | O5: =SUM(K5+M5) -> 0 | P5: 0 | Q5: =(E5+I5)/C5 -> 1 | R5: 0
B6: Desktop | C6: =COUNTA('Desktop Sanity'!D2:D1005) -> 53 | D6: 0 | E6: =COUNTIF('Desktop Sanity'!K2:K1005,"NA") -> 6 | F6: 0 | G6: =C6-(I6+O6+E6) -> 0 | H6: 0 | I6: =COUNTIF('Desktop Sanity'!K2:K1005,"Pass") -> 47 | J6: 0 | K6: =COUNTIF('Desktop Sanity'!K2:K1005,"Fail") -> 0 | L6: 0 | M6: =COUNTIF('Desktop Sanity'!K2:K1005,"Blocked") -> 0 | N6: 0 | O6: =SUM(K6+M6) -> 0 | P6: 0 | Q6: =(E6+I6)/C6 -> 1 | R6: 0
A7: Sanity New Framework | B7: Portal | C7: =COUNTA('Portal Sanity'!D2:D1005) -> 110 | D7: 0 | E7: =COUNTIF('Portal Sanity'!O2:O1005,"NA") -> 1 | F7: 0 | G7: =C7-(I7+O7+E7) -> 0 | H7: 0 | I7: =COUNTIF('Portal Sanity'!O2:O1005,"Pass") -> 109 | J7: 0 | K7: =COUNTIF('Portal Sanity'!O2:O1005,"Fail") -> 0 | L7: 0 | M7: =COUNTIF('Portal Sanity'!O2:O1005,"Blocked") -> 0 | N7: 0 | O7: =SUM(K7+M7) -> 0 | P7: 0 | Q7: =(E7+I7)/C7 -> 1 | R7: 0
B8: Mobile | C8: =COUNTA('Mobile Sanity'!D2:D1005) -> 111 | D8: 0 | E8: =COUNTIF('Mobile Sanity'!O2:O1005,"NA") -> 5 | F8: 0 | G8: =C8-(I8+O8+E8) -> 0 | H8: 0 | I8: =COUNTIF('Mobile Sanity'!O2:O1005,"Pass") -> 106 | J8: 0 | K8: =COUNTIF('Mobile Sanity'!O2:O1005,"Fail") -> 0 | L8: 0 | M8: =COUNTIF('Mobile Sanity'!O2:O1005,"Blocked") -> 0 | N8: 0 | O8: =SUM(K8+M8) -> 0 | P8: 0 | Q8: =(E8+I8)/C8 -> 1 | R8: 0
B9: Desktop | C9: =COUNTA('Desktop Sanity'!D2:D1005) -> 53 | D9: 0 | E9: =COUNTIF('Desktop Sanity'!O2:O1005,"NA") -> 6 | F9: 0 | G9: =C9-(I9+O9+E9) -> 0 | H9: 0 | I9: =COUNTIF('Desktop Sanity'!O2:O1005,"Pass") -> 47 | J9: 0 | K9: =COUNTIF('Desktop Sanity'!S2:S1005,"Fail") -> 0 | L9: 0 | M9: =COUNTIF('Desktop Sanity'!S2:S1005,"Blocked") -> 0 | N9: 0 | O9: =SUM(K9+M9) -> 0 | P9: 0 | Q9: =(E9+I9)/C9 -> 1 | R9: 0
A10: 7.0.0 New Feature S1 Defects | B10: Portal/Mobile/Offline Desktop | C10: =COUNTA('7.0.0 New Feature S1 Defects'!B2:B1005) -> 45 | D10: 0 | E10: =COUNTIF('7.0.0 New Feature S1 Defects'!E2:E1005,"NA") -> 1 | F10: 0 | G10: =C10-(I10+O10+E10) -> 0 | H10: 0 | I10: =COUNTIF('7.0.0 New Feature S1 Defects'!E2:E1005,"Pass") -> 44 | J10: 0 | K10: =COUNTIF('7.0.0 New Feature S1 Defects'!E2:E1005,"Fail") -> 0 | L10: 0 | M10: =COUNTIF('7.0.0 New Feature S1 Defects'!E2:E1005,"Blocked") -> 0 | N10: 0 | O10: =SUM(K10+M10) -> 0 | P10: 0 | Q10: =(E10+I10)/C10 -> 1 | R10: 0
A11: 6.0.0 OCI S1 Defects | B11: Portal/Mobile/Offline Desktop | C11: =COUNTA('6.0.0 OCI S1 Defects'!B2:B1005) -> 46 | D11: 0 | E11: =COUNTIF('6.0.0 OCI S1 Defects'!E2:E1005,"NA") -> 1 | F11: 0 | G11: =C11-(I11+O11+E11) -> 0 | H11: 0 | I11: =COUNTIF('6.0.0 OCI S1 Defects'!E2:E1005,"Pass") -> 45 | J11: 0 | K11: =COUNTIF('6.0.0 OCI S1 Defects'!E2:E1005,"Fail") -> 0 | L11: 0 | M11: =COUNTIF('6.0.0 OCI S1 Defects'!E2:E1005,"Blocked") -> 0 | N11: 0 | O11: =SUM(K11+M11) -> 0 | P11: 0 | Q11: =(E11+I11)/C11 -> 1 | R11: 0
A12: WorkSpace | B12: Portal | C12: =COUNTIF(Workspace!F2:F1005,"P1") -> 264 | D12: =COUNTIF(Workspace!F2:F1005,"P2") -> 327 | E12: =COUNTIFS(Workspace!F2:F1005,"P1",Workspace!T2:T1005,"NA") -> 14 | F12: =COUNTIFS(Workspace!F2:F1005,"P2",Workspace!T2:T1005,"NA") -> 26 | G12: =C12-(I12+K12+M12+E12) -> 0 | H12: =D12-(J12+L12+N12+F12) -> 0 | I12: =COUNTIFS(Workspace!F2:F1005,"P1",Workspace!T2:T1005,"Pass") -> 250 | J12: =COUNTIFS(Workspace!F2:F1005,"P2",Workspace!T2:T1005,"Pass") -> 301 | K12: =COUNTIFS(Workspace!F2:F1005,"P1",Workspace!T2:T1005,"Fail") -> 0 | L12: =COUNTIFS(Workspace!F2:F1005,"P2",Workspace!T2:T1005,"Fail") -> 0 | M12: =COUNTIFS(Workspace!F2:F1005,"P1",Workspace!T2:T1005,"Blocked") -> 0 | N12: =COUNTIFS(Workspace!F2:F1005,"P2",Workspace!T2:T1005,"Blocked") -> 0 | O12: =SUM(K12+M12) -> 0 | P12: =SUM(L12+N12) -> 0 | Q12: =(E12+I12)/C12 -> 1 | R12: =(F12+J12)/D12 -> 1
A13: Login | B13: Portal | C13: =COUNTIFS(Login!D2:D1005,"Reference Learning Web App",Login!F2:F1005,"P1") -> 61 | D13: =COUNTIFS(Login!D2:D1005,"Reference Learning Web App",Login!F2:F1005,"P2") -> 73 | E13: =COUNTIFS(Login!D2:D1005,"Reference Learning Web App",Login!F2:F1005,"P1",Login!R2:R1005,"NA") -> 2 | F13: =COUNTIFS(Login!D2:D1005,"Reference Learning Web App",Login!F2:F1005,"P2",Login!R2:R1005,"NA") -> 5 | G13: =C13-(I13+K13+M13+E13) -> 0 | H13: =D13-(J13+L13+N13+F13) -> 0 | I13: =COUNTIFS(Login!D2:D1005,"Reference Learning Web App",Login!F2:F1005,"P1",Login!R2:R1005,"Pass") -> 59 | J13: =COUNTIFS(Login!D2:D1005,"Reference Learning Web App",Login!F2:F1005,"P2",Login!R2:R1005,"Pass") -> 68 | K13: =COUNTIFS(Login!D2:D1005,"Reference Learning Web App",Login!F2:F1005,"P1",Login!R2:R1005,"Fail") -> 0 | L13: =COUNTIFS(Login!D2:D1005,"Reference Learning Web App",Login!F2:F1005,"P2",Login!R2:R1005,"Fail") -> 0 | M13: =COUNTIFS(Login!D2:D1005,"Reference Learning Web App",Login!F2:F1005,"P1",Login!R2:R1005,"Blocked") -> 0 | N13: =COUNTIFS(Login!D2:D1005,"Reference Learning Web App",Login!F2:F1005,"P2",Login!R2:R1005,"Blocked") -> 0 | O13: =SUM(K13+M13) -> 0 | P13: =SUM(L13+N13) -> 0 | Q13: =(E13+I13)/C13 -> 1 | R13: =(F13+J13)/D13 -> 1
B14: Mobile | C14: =COUNTIFS(Login!D2:D1005,"Reference Learning Mobile App",Login!F2:F1005,"P1") -> 62 | D14: =COUNTIFS(Login!D2:D1005,"Reference Learning Mobile App",Login!F2:F1005,"P2") -> 87 | E14: =COUNTIFS(Login!D2:D1005,"Reference Learning Mobile App",Login!F2:F1005,"P1",Login!R2:R1005,"NA") -> 1 | F14: =COUNTIFS(Login!D2:D1005,"Reference Learning Mobile App",Login!F2:F1005,"P2",Login!R2:R1005,"NA") -> 4 | G14: =C14-(I14+K14+M14+E14) -> 0 | H14: =D14-(J14+L14+N14+F14) -> 0 | I14: =COUNTIFS(Login!D2:D1005,"Reference Learning Mobile App",Login!F2:F1005,"P1",Login!R2:R1005,"Pass") -> 61 | J14: =COUNTIFS(Login!D2:D1005,"Reference Learning Mobile App",Login!F2:F1005,"P2",Login!R2:R1005,"Pass") -> 83 | K14: =COUNTIFS(Login!D2:D1005,"Reference Learning Mobile App",Login!F2:F1005,"P1",Login!R2:R1005,"Fail") -> 0 | L14: =COUNTIFS(Login!D2:D1005,"Reference Learning Mobile App",Login!F2:F1005,"P2",Login!R2:R1005,"Fail") -> 0 | M14: =COUNTIFS(Login!D2:D1005,"Reference Learning Mobile App",Login!F2:F1005,"P1",Login!R2:R1005,"Blocked") -> 0 | N14: =COUNTIFS(Login!D2:D1005,"Reference Learning Mobile App",Login!F2:F1005,"P2",Login!R2:R1005,"Blocked") -> 0 | O14: =SUM(K14+M14) -> 0 | P14: =SUM(L14+N14) -> 0 | Q14: =(E14+I14)/C14 -> 1 | R14: =(F14+J14)/D14 -> 1
B15: Offline Desktop | C15: =COUNTIFS(Login!D2:D1005,"Reference Learning Desktop App",Login!F2:F1005,"P1") -> 22 | D15: =COUNTIFS(Login!D2:D1005,"Reference Learning Desktop App",Login!F2:F1005,"P2") -> 26 | E15: =COUNTIFS(Login!D2:D1005,"Reference Learning Desktop App",Login!F2:F1005,"P1",Login!R2:R1005,"NA") -> 0 | F15: =COUNTIFS(Login!D2:D1005,"Reference Learning Desktop App",Login!F2:F1005,"P2",Login!R2:R1005,"NA") -> 0 | G15: =C15-(I15+K15+M15+E15) -> 0 | H15: =D15-(J15+L15+N15+F15) -> 0 | I15: =COUNTIFS(Login!D2:D1005,"Reference Learning Desktop App",Login!F2:F1005,"P1",Login!R2:R1005,"Pass") -> 22 | J15: =COUNTIFS(Login!D2:D1005,"Reference Learning Desktop App",Login!F2:F1005,"P2",Login!R2:R1005,"Pass") -> 26 | K15: =COUNTIFS(Login!D2:D1005,"Reference Learning Desktop App",Login!F2:F1005,"P1",Login!R2:R1005,"Fail") -> 0 | L15: =COUNTIFS(Login!D2:D1005,"Reference Learning Desktop App",Login!F2:F1005,"P2",Login!R2:R1005,"Fail") -> 0 | M15: =COUNTIFS(Login!D2:D1005,"Reference Learning Desktop App",Login!F2:F1005,"P1",Login!R2:R1005,"Blocked") -> 0 | N15: =COUNTIFS(Login!D2:D1005,"Reference Learning Desktop App",Login!F2:F1005,"P2",Login!R2:R1005,"Blocked") -> 0 | O15: =SUM(K15+M15) -> 0 | P15: =SUM(L15+N15) -> 0 | Q15: =(E15+I15)/C15 -> 1 | R15: =(F15+J15)/D15 -> 1
A16: Course Consumption | B16: Portal | C16: =COUNTIFS('Course Consumption'!D2:D1005,"Reference Learning Web App",'Course Consumption'!F2:F1005,"P1") -> 163 | D16: =COUNTIFS('Course Consumption'!D2:D1005,"Reference Learning Web App",'Course Consumption'!F2:F1005,"P2") -> 59 | E16: =COUNTIFS('Course Consumption'!D2:D1005,"Reference Learning Web App",'Course Consumption'!F2:F1005,"P1",'Course Consumption'!R2:R1005,"NA") -> 8 | F16: =COUNTIFS('Course Consumption'!D2:D1005,"Reference Learning Web App",'Course Consumption'!F2:F1005,"P2",'Course Consumption'!R2:R1005,"NA") -> 1 | G16: =C16-(I16+K16+M16+E16) -> 0 | H16: =D16-(J16+L16+N16+F16) -> 0 | I16: =COUNTIFS('Course Consumption'!D2:D1005,"Reference Learning Web App",'Course Consumption'!F2:F1005,"P1",'Course Consumption'!R2:R1005,"Pass") -> 155 | J16: =COUNTIFS('Course Consumption'!D2:D1005,"Reference Learning Web App",'Course Consumption'!F2:F1005,"P2",'Course Consumption'!R2:R1005,"Pass") -> 58 | K16: =COUNTIFS('Course Consumption'!D2:D1005,"Reference Learning Web App",'Course Consumption'!F2:F1005,"P1",'Course Consumption'!R2:R1005,"Fail") -> 0 | L16: =COUNTIFS('Course Consumption'!D2:D1005,"Reference Learning Web App",'Course Consumption'!F2:F1005,"P2",'Course Consumption'!R2:R1005,"Fail") -> 0 | M16: =COUNTIFS('Course Consumption'!D2:D1005,"Reference Learning Web App",'Course Consumption'!F2:F1005,"P1",'Course Consumption'!R2:R1005,"Blocked") -> 0 | N16: =COUNTIFS('Course Consumption'!D2:D1005,"Reference Learning Web App",'Course Consumption'!F2:F1005,"P2",'Course Consumption'!R2:R1005,"Blocked") -> 0 | O16: =SUM(K16+M16) -> 0 | P16: =SUM(L16+N16) -> 0 | Q16: =(E16+I16)/C16 -> 1 | R16: =(F16+J16)/D16 -> 1
B17: Mobile | C17: =COUNTIFS('Course Consumption'!D2:D1005,"Reference Learning Mobile App",'Course Consumption'!F2:F1005,"P1") -> 119 | D17: =COUNTIFS('Course Consumption'!D2:D1005,"Reference Learning Mobile App",'Course Consumption'!F2:F1005,"P2") -> 164 | E17: =COUNTIFS('Course Consumption'!D2:D1005,"Reference Learning Mobile App",'Course Consumption'!F2:F1005,"P1",'Course Consumption'!R2:R1005,"NA") -> 3 | F17: =COUNTIFS('Course Consumption'!D2:D1005,"Reference Learning Mobile App",'Course Consumption'!F2:F1005,"P2",'Course Consumption'!R2:R1005,"NA") -> 7 | G17: =C17-(I17+K17+M17+E17) -> 0 | H17: =D17-(J17+L17+N17+F17) -> 0 | I17: =COUNTIFS('Course Consumption'!D2:D1005,"Reference Learning Mobile App",'Course Consumption'!F2:F1005,"P1",'Course Consumption'!R2:R1005,"Pass") -> 116 | J17: =COUNTIFS('Course Consumption'!D2:D1005,"Reference Learning Mobile App",'Course Consumption'!F2:F1005,"P2",'Course Consumption'!R2:R1005,"Pass") -> 157 | K17: =COUNTIFS('Course Consumption'!D2:D1005,"Reference Learning Mobile App",'Course Consumption'!F2:F1005,"P1",'Course Consumption'!R2:R1005,"Fail") -> 0 | L17: =COUNTIFS('Course Consumption'!D2:D1005,"Reference Learning Mobile App",'Course Consumption'!F2:F1005,"P2",'Course Consumption'!R2:R1005,"Fail") -> 0 | M17: =COUNTIFS('Course Consumption'!D2:D1005,"Reference Learning Mobile App",'Course Consumption'!F2:F1005,"P1",'Course Consumption'!R2:R1005,"Blocked") -> 0 | N17: =COUNTIFS('Course Consumption'!D2:D1005,"Reference Learning Mobile App",'Course Consumption'!F2:F1005,"P2",'Course Consumption'!R2:R1005,"Blocked") -> 0 | O17: =SUM(K17+M17) -> 0 | P17: =SUM(L17+N17) -> 0 | Q17: =(E17+I17)/C17 -> 1 | R17: =(F17+J17)/D17 -> 1
B18: Offline Desktop | C18: =COUNTIFS('Course Consumption'!D2:D1005,"Reference Learning Desktop App",'Course Consumption'!F2:F1005,"P1") -> 40 | D18: =COUNTIFS('Course Consumption'!D2:D1005,"Reference Learning Desktop App",'Course Consumption'!F2:F1005,"P2") -> 38 | E18: =COUNTIFS('Course Consumption'!D2:D1005,"Reference Learning Desktop App",'Course Consumption'!F2:F1005,"P1",'Course Consumption'!R2:R1005,"NA") -> 3 | F18: =COUNTIFS('Course Consumption'!D2:D1005,"Reference Learning Desktop App",'Course Consumption'!F2:F1005,"P2",'Course Consumption'!R2:R1005,"NA") -> 2 | G18: =C18-(I18+K18+M18+E18) -> 0 | H18: =D18-(J18+L18+N18+F18) -> 0 | I18: =COUNTIFS('Course Consumption'!D2:D1005,"Reference Learning Desktop App",'Course Consumption'!F2:F1005,"P1",'Course Consumption'!R2:R1005,"Pass") -> 37 | J18: =COUNTIFS('Course Consumption'!D2:D1005,"Reference Learning Desktop App",'Course Consumption'!F2:F1005,"P2",'Course Consumption'!R2:R1005,"Pass") -> 36 | K18: =COUNTIFS('Course Consumption'!D2:D1005,"Reference Learning Desktop App",'Course Consumption'!F2:F1005,"P1",'Course Consumption'!R2:R1005,"Fail") -> 0 | L18: =COUNTIFS('Course Consumption'!D2:D1005,"Reference Learning Desktop App",'Course Consumption'!F2:F1005,"P2",'Course Consumption'!R2:R1005,"Fail") -> 0 | M18: =COUNTIFS('Course Consumption'!D2:D1005,"Reference Learning Desktop App",'Course Consumption'!F2:F1005,"P1",'Course Consumption'!R2:R1005,"Blocked") -> 0 | N18: =COUNTIFS('Course Consumption'!D2:D1005,"Reference Learning Desktop App",'Course Consumption'!F2:F1005,"P2",'Course Consumption'!R2:R1005,"Blocked") -> 0 | O18: =SUM(K18+M18) -> 0 | P18: =SUM(L18+N18) -> 0 | Q18: =(E18+I18)/C18 -> 1 | R18: =(F18+J18)/D18 -> 1
A19: Batch Creation | B19: Portal | C19: =COUNTIFS('Batch Creation'!D2:D1005,"Reference Learning Web App",'Batch Creation'!F2:F1005,"P1") -> 43 | D19: =COUNTIFS('Batch Creation'!D2:D1005,"Reference Learning Web App",'Batch Creation'!F2:F1005,"P2") -> 10 | E19: =COUNTIFS('Batch Creation'!D2:D1005,"Reference Learning Web App",'Batch Creation'!F2:F1005,"P1",'Batch Creation'!Q2:Q1005,"NA") -> 0 | F19: =COUNTIFS('Batch Creation'!D2:D1005,"Reference Learning Web App",'Batch Creation'!F2:F1005,"P2",'Batch Creation'!Q2:Q1005,"NA") -> 0 | G19: =C19-(I19+K19+M19+E19) -> 0 | H19: =D19-(J19+L19+N19+F19) -> 0 | I19: =COUNTIFS('Batch Creation'!D2:D1005,"Reference Learning Web App",'Batch Creation'!F2:F1005,"P1",'Batch Creation'!Q2:Q1005,"Pass") -> 43 | J19: =COUNTIFS('Batch Creation'!D2:D1005,"Reference Learning Web App",'Batch Creation'!F2:F1005,"P2",'Batch Creation'!Q2:Q1005,"Pass") -> 10 | K19: =COUNTIFS('Batch Creation'!D2:D1005,"Reference Learning Web App",'Batch Creation'!F2:F1005,"P1",'Batch Creation'!Q2:Q1005,"Fail") -> 0 | L19: =COUNTIFS('Batch Creation'!D2:D1005,"Reference Learning Web App",'Batch Creation'!F2:F1005,"P2",'Batch Creation'!Q2:Q1005,"Fail") -> 0 | M19: =COUNTIFS('Batch Creation'!D2:D1005,"Reference Learning Web App",'Batch Creation'!F2:F1005,"P1",'Batch Creation'!Q2:Q1005,"Blocked") -> 0 | N19: =COUNTIFS('Batch Creation'!D2:D1005,"Reference Learning Web App",'Batch Creation'!F2:F1005,"P2",'Batch Creation'!Q2:Q1005,"Blocked") -> 0 | O19: =SUM(K19+M19) -> 0 | P19: =SUM(L19+N19) -> 0 | Q19: =(E19+I19)/C19 -> 1 | R19: =(F19+J19)/D19 -> 1
A20: Digital Textbook Consumption | B20: Portal | C20: =COUNTIFS('Digital Textbook Consumption'!D2:D1005,"Reference Learning Web App",'Digital Textbook Consumption'!F2:F1005,"P1") -> 41 | D20: =COUNTIFS('Digital Textbook Consumption'!D2:D1005,"Reference Learning Web App",'Digital Textbook Consumption'!F2:F1005,"P2") -> 30 | E20: =COUNTIFS('Digital Textbook Consumption'!D5:D1005,"Reference Learning Web App",'Digital Textbook Consumption'!F5:F1005,"P1",'Digital Textbook Consumption'!Q5:Q1005,"NA") -> 0 | F20: =COUNTIFS('Digital Textbook Consumption'!D2:D1005,"Reference Learning Web App",'Digital Textbook Consumption'!F2:F1005,"P2",'Digital Textbook Consumption'!Q2:Q1005,"NA") -> 3 | G20: =C20-(I20+K20+M20+E20) -> 0 | H20: =D20-(J20+L20+N20+F20) -> 0 | I20: =COUNTIFS('Digital Textbook Consumption'!D2:D1005,"Reference Learning Web App",'Digital Textbook Consumption'!F2:F1005,"P1",'Digital Textbook Consumption'!Q2:Q1005,"Pass") -> 41 | J20: =COUNTIFS('Digital Textbook Consumption'!D2:D1005,"Reference Learning Web App",'Digital Textbook Consumption'!F2:F1005,"P2",'Digital Textbook Consumption'!Q2:Q1005,"Pass") -> 27 | K20: =COUNTIFS('Digital Textbook Consumption'!D2:D1005,"Reference Learning Web App",'Digital Textbook Consumption'!F2:F1005,"P1",'Digital Textbook Consumption'!Q2:Q1005,"Fail") -> 0 | L20: =COUNTIFS('Digital Textbook Consumption'!D2:D1005,"Reference Learning Web App",'Digital Textbook Consumption'!F2:F1005,"P2",'Digital Textbook Consumption'!Q2:Q1005,"Fail") -> 0 | M20: =COUNTIFS('Digital Textbook Consumption'!D2:D1005,"Reference Learning Web App",'Digital Textbook Consumption'!F2:F1005,"P1",'Digital Textbook Consumption'!Q2:Q1005,"Blocked") -> 0 | N20: =COUNTIFS('Digital Textbook Consumption'!D2:D1005,"Reference Learning Web App",'Digital Textbook Consumption'!F2:F1005,"P2",'Digital Textbook Consumption'!Q2:Q1005,"Blocked") -> 0 | O20: =SUM(K20+M20) -> 0 | P20: =SUM(L20+N20) -> 0 | Q20: =(E20+I20)/C20 -> 1 | R20: =(F20+J20)/D20 -> 1
B21: Mobile | C21: =COUNTIFS('Digital Textbook Consumption'!D2:D1005,"Reference Learning Mobile App",'Digital Textbook Consumption'!F2:F1005,"P1") -> 23 | D21: =COUNTIFS('Digital Textbook Consumption'!D2:D1005,"Reference Learning Mobile App",'Digital Textbook Consumption'!F2:F1005,"P2") -> 34 | E21: =COUNTIFS('Digital Textbook Consumption'!D2:D1005,"Reference Learning Mobile App",'Digital Textbook Consumption'!F2:F1005,"P1",'Digital Textbook Consumption'!Q2:Q1005,"NA") -> 1 | F21: =COUNTIFS('Digital Textbook Consumption'!D2:D1005,"Reference Learning Mobile App",'Digital Textbook Consumption'!F2:F1005,"P2",'Digital Textbook Consumption'!Q2:Q1005,"NA") -> 0 | G21: =C21-(I21+K21+M21+E21) -> 0 | H21: =D21-(J21+L21+N21+F21) -> 0 | I21: =COUNTIFS('Digital Textbook Consumption'!D2:D1005,"Reference Learning Mobile App",'Digital Textbook Consumption'!F2:F1005,"P1",'Digital Textbook Consumption'!Q2:Q1005,"Pass") -> 22 | J21: =COUNTIFS('Digital Textbook Consumption'!D2:D1005,"Reference Learning Mobile App",'Digital Textbook Consumption'!F2:F1005,"P2",'Digital Textbook Consumption'!Q2:Q1005,"Pass") -> 34 | K21: =COUNTIFS('Digital Textbook Consumption'!D2:D1005,"Reference Learning Mobile App",'Digital Textbook Consumption'!F2:F1005,"P1",'Digital Textbook Consumption'!Q2:Q1005,"Fail") -> 0 | L21: =COUNTIFS('Digital Textbook Consumption'!D2:D1005,"Reference Learning Mobile App",'Digital Textbook Consumption'!F2:F1005,"P2",'Digital Textbook Consumption'!Q2:Q1005,"Fail") -> 0 | M21: =COUNTIFS('Digital Textbook Consumption'!D2:D1005,"Reference Learning Mobile App",'Digital Textbook Consumption'!F2:F1005,"P1",'Digital Textbook Consumption'!Q2:Q1005,"Blocked") -> 0 | N21: =COUNTIFS('Digital Textbook Consumption'!D2:D1005,"Reference Learning Mobile App",'Digital Textbook Consumption'!F2:F1005,"P2",'Digital Textbook Consumption'!Q2:Q1005,"Blocked") -> 0 | O21: =SUM(K21+M21) -> 0 | P21: =SUM(L21+N21) -> 0 | Q21: =(E21+I21)/C21 -> 1 | R21: =(F21+J21)/D21 -> 1
B22: Offline Desktop | C22: =COUNTIFS('Digital Textbook Consumption'!D2:D1005,"Reference Learning Desktop App",'Digital Textbook Consumption'!F2:F1005,"P1") -> 15 | D22: =COUNTIFS('Digital Textbook Consumption'!D2:D1005,"Reference Learning Desktop App",'Digital Textbook Consumption'!F2:F1005,"P2") -> 41 | E22: =COUNTIFS('Digital Textbook Consumption'!D2:D1005,"Reference Learning Desktop App",'Digital Textbook Consumption'!F2:F1005,"P1",'Digital Textbook Consumption'!Q2:Q1005,"NA") -> 2 | F22: =COUNTIFS('Digital Textbook Consumption'!D2:D1005,"Reference Learning Desktop App",'Digital Textbook Consumption'!F2:F1005,"P2",'Digital Textbook Consumption'!Q2:Q1005,"NA") -> 2 | G22: =C22-(I22+K22+M22+E22) -> 0 | H22: =D22-(J22+L22+N22+F22) -> 0 | I22: =COUNTIFS('Digital Textbook Consumption'!D2:D1005,"Reference Learning Desktop App",'Digital Textbook Consumption'!F2:F1005,"P1",'Digital Textbook Consumption'!Q2:Q1005,"Pass") -> 13 | J22: =COUNTIFS('Digital Textbook Consumption'!D2:D1005,"Reference Learning Desktop App",'Digital Textbook Consumption'!F2:F1005,"P2",'Digital Textbook Consumption'!Q2:Q1005,"Pass") -> 39 | K22: =COUNTIFS('Digital Textbook Consumption'!D2:D1005,"Reference Learning Desktop App",'Digital Textbook Consumption'!F2:F1005,"P1",'Digital Textbook Consumption'!Q2:Q1005,"Fail") -> 0 | L22: =COUNTIFS('Digital Textbook Consumption'!D2:D1005,"Reference Learning Desktop App",'Digital Textbook Consumption'!F2:F1005,"P2",'Digital Textbook Consumption'!Q2:Q1005,"Fail") -> 0 | M22: =COUNTIFS('Digital Textbook Consumption'!D2:D1005,"Reference Learning Desktop App",'Digital Textbook Consumption'!F2:F1005,"P1",'Digital Textbook Consumption'!Q2:Q1005,"Blocked") -> 0 | N22: =COUNTIFS('Digital Textbook Consumption'!D2:D1005,"Reference Learning Desktop App",'Digital Textbook Consumption'!F2:F1005,"P2",'Digital Textbook Consumption'!Q2:Q1005,"Blocked") -> 0 | O22: =SUM(K22+M22) -> 0 | P22: =SUM(L22+N22) -> 0 | Q22: =(E22+I22)/C22 -> 1 | R22: =(F22+J22)/D22 -> 1
A23: Content Consumption | B23: Portal | C23: =COUNTIFS('Content Consumption'!D2:D1005,"Reference Learning Web App",'Content Consumption'!F2:F1005,"P1") -> 90 | D23: =COUNTIFS('Content Consumption'!D2:D1005,"Reference Learning Web App",'Content Consumption'!F2:F1005,"P2") -> 52 | E23: =COUNTIFS('Content Consumption'!D5:D1005,"Reference Learning Web App",'Content Consumption'!F5:F1005,"P1",'Content Consumption'!Q5:Q1005,"NA") -> 0 | F23: =COUNTIFS('Content Consumption'!D2:D1005,"Reference Learning Web App",'Content Consumption'!F2:F1005,"P2",'Content Consumption'!R2:R1005,"NA") -> 1 | G23: =C23-(I23+K23+M23+E23) -> 0 | H23: =D23-(J23+L23+N23+F23) -> 0 | I23: =COUNTIFS('Content Consumption'!D2:D1005,"Reference Learning Web App",'Content Consumption'!F2:F1005,"P1",'Content Consumption'!R2:R1005,"Pass") -> 90 | J23: =COUNTIFS('Content Consumption'!D2:D1005,"Reference Learning Web App",'Content Consumption'!F2:F1005,"P2",'Content Consumption'!R2:R1005,"Pass") -> 51 | K23: =COUNTIFS('Content Consumption'!D2:D1005,"Reference Learning Web App",'Content Consumption'!F2:F1005,"P1",'Content Consumption'!R2:R1005,"Fail") -> 0 | L23: =COUNTIFS('Content Consumption'!D2:D1005,"Reference Learning Web App",'Content Consumption'!F2:F1005,"P2",'Content Consumption'!R2:R1005,"Fail") -> 0 | M23: =COUNTIFS('Content Consumption'!D2:D1005,"Reference Learning Web App",'Content Consumption'!F2:F1005,"P1",'Content Consumption'!R2:R1005,"Blocked") -> 0 | N23: =COUNTIFS('Content Consumption'!D2:D1005,"Reference Learning Web App",'Content Consumption'!F2:F1005,"P2",'Content Consumption'!R2:R1005,"Blocked") -> 0 | O23: =SUM(K23+M23) -> 0 | P23: =SUM(L23+N23) -> 0 | Q23: =(E23+I23)/C23 -> 1 | R23: =(F23+J23)/D23 -> 1
B24: Mobile | C24: =COUNTIFS('Content Consumption'!D2:D1005,"Reference Learning Mobile App",'Content Consumption'!F2:F1005,"P1") -> 31 | D24: =COUNTIFS('Content Consumption'!D3:D1005,"Reference Learning Mobile App",'Content Consumption'!F3:F1005,"P2") -> 84 | E24: =COUNTIFS('Content Consumption'!D2:D1005,"Reference Learning Mobile App",'Content Consumption'!F2:F1005,"P1",'Content Consumption'!R2:R1005,"NA") -> 1 | F24: =COUNTIFS('Content Consumption'!D2:D1005,"Reference Learning Mobile App",'Content Consumption'!F2:F1005,"P2",'Content Consumption'!R2:R1005,"NA") -> 0 | G24: =C24-(I24+K24+M24+E24) -> 0 | H24: =D24-(J24+L24+N24+F24) -> 0 | I24: =COUNTIFS('Content Consumption'!D2:D1005,"Reference Learning Mobile App",'Content Consumption'!F2:F1005,"P1",'Content Consumption'!R2:R1005,"Pass") -> 30 | J24: =COUNTIFS('Content Consumption'!D2:D1005,"Reference Learning Mobile App",'Content Consumption'!F2:F1005,"P2",'Content Consumption'!R2:R1005,"Pass") -> 84 | K24: =COUNTIFS('Content Consumption'!D2:D1005,"Reference Learning Mobile App",'Content Consumption'!F2:F1005,"P1",'Content Consumption'!R2:R1005,"Fail") -> 0 | L24: =COUNTIFS('Content Consumption'!D2:D1005,"Reference Learning Mobile App",'Content Consumption'!F2:F1005,"P2",'Content Consumption'!R2:R1005,"Fail") -> 0 | M24: =COUNTIFS('Content Consumption'!D2:D1005,"Reference Learning Mobile App",'Content Consumption'!F2:F1005,"P1",'Content Consumption'!R2:R1005,"Blocked") -> 0 | N24: =COUNTIFS('Content Consumption'!D2:D1005,"Reference Learning Mobile App",'Content Consumption'!F2:F1005,"P2",'Content Consumption'!R2:R1005,"Blocked") -> 0 | O24: =SUM(K24+M24) -> 0 | P24: =SUM(L24+N24) -> 0 | Q24: =(E24+I24)/C24 -> 1 | R24: =(F24+J24)/D24 -> 1
B25: Offline Desktop | C25: =COUNTIFS('Content Consumption'!D2:D1005,"Reference Learning Desktop App",'Content Consumption'!F2:F1005,"P1") -> 42 | D25: =COUNTIFS('Content Consumption'!D3:D1005,"Reference Learning Desktop App",'Content Consumption'!F3:F1005,"P2") -> 32 | E25: =COUNTIFS('Content Consumption'!D2:D1005,"Reference Learning Desktop App",'Content Consumption'!F2:F1005,"P1",'Content Consumption'!R2:R1005,"NA") -> 0 | F25: =COUNTIFS('Content Consumption'!D2:D1005,"Reference Learning Desktop App",'Content Consumption'!F2:F1005,"P2",'Content Consumption'!R2:R1005,"NA") -> 0 | G25: =C25-(I25+K25+M25+E25) -> 0 | H25: =D25-(J25+L25+N25+F25) -> 0 | I25: =COUNTIFS('Content Consumption'!D2:D1005,"Reference Learning Desktop App",'Content Consumption'!F2:F1005,"P1",'Content Consumption'!R2:R1005,"Pass") -> 42 | J25: =COUNTIFS('Content Consumption'!D2:D1005,"Reference Learning Desktop App",'Content Consumption'!F2:F1005,"P2",'Content Consumption'!R2:R1005,"Pass") -> 32 | K25: =COUNTIFS('Content Consumption'!D2:D1005,"Reference Learning Desktop App",'Content Consumption'!F2:F1005,"P1",'Content Consumption'!R2:R1005,"Fail") -> 0 | L25: =COUNTIFS('Content Consumption'!D2:D1005,"Reference Learning Desktop App",'Content Consumption'!F2:F1005,"P2",'Content Consumption'!R2:R1005,"Fail") -> 0 | M25: =COUNTIFS('Content Consumption'!D2:D1005,"Reference Learning Desktop App",'Content Consumption'!F2:F1005,"P1",'Content Consumption'!R2:R1005,"Blocked") -> 0 | N25: =COUNTIFS('Content Consumption'!D2:D1005,"Reference Learning Desktop App",'Content Consumption'!F2:F1005,"P2",'Content Consumption'!R2:R1005,"Blocked") -> 0 | O25: =SUM(K25+M25) -> 0 | P25: =SUM(L25+N25) -> 0 | Q25: =(E25+I25)/C25 -> 1 | R25: =(F25+J25)/D25 -> 1
A26: Profile | B26: Portal | C26: =COUNTIFS(Profile!D2:D1005,"Reference Learning Web App",Profile!F2:F1005,"P1") -> 42 | D26: =COUNTIFS(Profile!D2:D1005,"Reference Learning Web App",Profile!F2:F1005,"P2") -> 74 | E26: =COUNTIFS(Profile!D5:D1005,"Reference Learning Web App",Profile!F5:F1005,"P1",Profile!Q5:Q1005,"NA") -> 0 | F26: =COUNTIFS(Profile!D2:D1005,"Reference Learning Web App",Profile!F2:F1005,"P2",Profile!R2:R1005,"NA") -> 3 | G26: =C26-(I26+K26+M26+E26) -> 0 | H26: =D26-(J26+L26+N26+F26) -> 0 | I26: =COUNTIFS(Profile!D2:D1005,"Reference Learning Web App",Profile!F2:F1005,"P1",Profile!R2:R1005,"Pass") -> 42 | J26: =COUNTIFS(Profile!D2:D1005,"Reference Learning Web App",Profile!F2:F1005,"P2",Profile!R2:R1005,"Pass") -> 71 | K26: =COUNTIFS(Profile!D2:D1005,"Reference Learning Web App",Profile!F2:F1005,"P1",Profile!R2:R1005,"Fail") -> 0 | L26: =COUNTIFS(Profile!D2:D1005,"Reference Learning Web App",Profile!F2:F1005,"P2",Profile!R2:R1005,"Fail") -> 0 | M26: =COUNTIFS(Profile!D2:D1005,"Reference Learning Web App",Profile!F2:F1005,"P1",Profile!R2:R1005,"Blocked") -> 0 | N26: =COUNTIFS(Profile!D2:D1005,"Reference Learning Web App",Profile!F2:F1005,"P2",Profile!R2:R1005,"Blocked") -> 0 | O26: =SUM(K26+M26) -> 0 | P26: =SUM(L26+N26) -> 0 | Q26: =(E26+I26)/C26 -> 1 | R26: =(F26+J26)/D26 -> 1
B27: Mobile | C27: =COUNTIFS(Profile!D2:D1005,"Reference Learning Mobile App",Profile!F2:F1005,"P1") -> 43 | D27: =COUNTIFS(Profile!D2:D1005,"Reference Learning Mobile App",Profile!F2:F1005,"P2") -> 51 | E27: =COUNTIFS(Profile!D5:D1005,"Reference Learning Mobile App",Profile!F5:F1005,"P1",Profile!Q5:Q1005,"NA") -> 0 | F27: =COUNTIFS(Profile!D2:D1005,"Reference Learning Mobile App",Profile!F2:F1005,"P2",Profile!R2:R1005,"NA") -> 0 | G27: =C27-(I27+K27+M27+E27) -> 0 | H27: =D27-(J27+L27+N27+F27) -> 0 | I27: =COUNTIFS(Profile!D2:D1005,"Reference Learning Mobile App",Profile!F2:F1005,"P1",Profile!R2:R1005,"Pass") -> 43 | J27: =COUNTIFS(Profile!D2:D1005,"Reference Learning Mobile App",Profile!F2:F1005,"P2",Profile!R2:R1005,"Pass") -> 51 | K27: =COUNTIFS(Profile!D2:D1005,"Reference Learning Mobile App",Profile!F2:F1005,"P1",Profile!R2:R1005,"Fail") -> 0 | L27: =COUNTIFS(Profile!D2:D1005,"Reference Learning Mobile App",Profile!F2:F1005,"P2",Profile!R2:R1005,"Fail") -> 0 | M27: =COUNTIFS(Profile!D2:D1005,"Reference Learning Mobile App",Profile!F2:F1005,"P1",Profile!R2:R1005,"Blocked") -> 0 | N27: =COUNTIFS(Profile!D2:D1005,"Reference Learning Mobile App",Profile!F2:F1005,"P2",Profile!R2:R1005,"Blocked") -> 0 | O27: =SUM(K27+M27) -> 0 | P27: =SUM(L27+N27) -> 0 | Q27: =(E27+I27)/C27 -> 1 | R27: =(F27+J27)/D27 -> 1
B28: Offline Desktop | C28: =COUNTIFS(Profile!D2:D1005,"Reference Learning Desktop App",Profile!F2:F1005,"P1") -> 28 | D28: =COUNTIFS(Profile!D2:D1005,"Reference Learning Desktop App",Profile!F2:F1005,"P2") -> 37 | E28: =COUNTIFS(Profile!D2:D1005,"Reference Learning Desktop App",Profile!F2:F1005,"P1",Profile!R2:R1005,"NA") -> 1 | F28: =COUNTIFS(Profile!D2:D1005,"Reference Learning Desktop App",Profile!F2:F1005,"P2",Profile!R2:R1005,"NA") -> 2 | G28: =C28-(I28+K28+M28+E28) -> 0 | H28: =D28-(J28+L28+N28+F28) -> 0 | I28: =COUNTIFS(Profile!D2:D1005,"Reference Learning Desktop App",Profile!F2:F1005,"P1",Profile!R2:R1005,"Pass") -> 27 | J28: =COUNTIFS(Profile!D2:D1005,"Reference Learning Desktop App",Profile!F2:F1005,"P2",Profile!R2:R1005,"Pass") -> 35 | K28: =COUNTIFS(Profile!D2:D1005,"Reference Learning Desktop App",Profile!F2:F1005,"P1",Profile!R2:R1005,"Fail") -> 0 | L28: =COUNTIFS(Profile!D2:D1005,"Reference Learning Desktop App",Profile!F2:F1005,"P2",Profile!R2:R1005,"Fail") -> 0 | M28: =COUNTIFS(Profile!D2:D1005,"Reference Learning Desktop App",Profile!F2:F1005,"P1",Profile!R2:R1005,"Blocked") -> 0 | N28: =COUNTIFS(Profile!D2:D1005,"Reference Learning Desktop App",Profile!F2:F1005,"P2",Profile!R2:R1005,"Blocked") -> 0 | O28: =SUM(K28+M28) -> 0 | P28: =SUM(L28+N28) -> 0 | Q28: =(E28+I28)/C28 -> 1 | R28: =(F28+J28)/D28 -> 1
A29: Course reports | B29: Portal | C29: =COUNTIFS('Course reports'!D2:D1005,"Reference Learning Web App",'Course reports'!F2:F1005,"P1") -> 20 | D29: =COUNTIFS('Course reports'!D2:D1005,"Reference Learning Web App",'Course reports'!F2:F1005,"P2") -> 7 | E29: =COUNTIFS('Course reports'!D2:D1005,"Reference Learning Web App",'Course reports'!F2:F1005,"P1",'Course reports'!Q2:Q1005,"NA") -> 3 | F29: =COUNTIFS('Course reports'!D2:D1005,"Reference Learning Web App",'Course reports'!F2:F1005,"P2",'Course reports'!Q2:Q1005,"NA") -> 0 | G29: =C29-(I29+K29+M29+E29) -> 0 | H29: =D29-(J29+L29+N29+F29) -> 0 | I29: =COUNTIFS('Course reports'!D2:D1005,"Reference Learning Web App",'Course reports'!F2:F1005,"P1",'Course reports'!Q2:Q1005,"Pass") -> 17 | J29: =COUNTIFS('Course reports'!D2:D1005,"Reference Learning Web App",'Course reports'!F2:F1005,"P2",'Course reports'!Q2:Q1005,"Pass") -> 7 | K29: =COUNTIFS('Course reports'!D2:D1005,"Reference Learning Web App",'Course reports'!F2:F1005,"P1",'Course reports'!Q2:Q1005,"Fail") -> 0 | L29: =COUNTIFS('Course reports'!D2:D1005,"Reference Learning Web App",'Course reports'!F2:F1005,"P2",'Course reports'!Q2:Q1005,"Fail") -> 0 | M29: =COUNTIFS('Course reports'!D2:D1005,"Reference Learning Web App",'Course reports'!F2:F1005,"P1",'Course reports'!Q2:Q1005,"Blocked") -> 0 | N29: =COUNTIFS('Course reports'!D2:D1005,"Reference Learning Web App",'Course reports'!F2:F1005,"P2",'Course reports'!Q2:Q1005,"Blocked") -> 0 | O29: =SUM(K29+M29) -> 0 | P29: =SUM(L29+N29) -> 0 | Q29: =(E29+I29)/C29 -> 1 | R29: =(F29+J29)/D29 -> 1
B30: Mobile | C30: =COUNTIFS('Course reports'!D2:D1005,"Reference Learning Mobile App",'Course reports'!F2:F1005,"P1") -> 0 | D30: =COUNTIFS('Course reports'!D2:D1005,"Reference Learning Mobile App",'Course reports'!F2:F1005,"P2") -> 2 | E30: =COUNTIFS('Course reports'!D2:D1005,"Reference Learning Mobile App",'Course reports'!F2:F1005,"P1",'Course reports'!Q2:Q1005,"NA") -> 0 | F30: =COUNTIFS('Course reports'!D2:D1005,"Reference Learning Mobile App",'Course reports'!F2:F1005,"P2",'Course reports'!Q2:Q1005,"NA") -> 0 | G30: =C30-(I30+K30+M30+E30) -> 0 | H30: =D30-(J30+L30+N30+F30) -> 0 | I30: =COUNTIFS('Course reports'!D2:D1005,"Reference Learning Mobile App",'Course reports'!F2:F1005,"P1",'Course reports'!Q2:Q1005,"Pass") -> 0 | J30: =COUNTIFS('Course reports'!D2:D1005,"Reference Learning Mobile App",'Course reports'!F2:F1005,"P2",'Course reports'!Q2:Q1005,"Pass") -> 2 | K30: =COUNTIFS('Course reports'!D2:D1005,"Reference Learning Mobile App",'Course reports'!F2:F1005,"P1",'Course reports'!Q2:Q1005,"Fail") -> 0 | L30: =COUNTIFS('Course reports'!D2:D1005,"Reference Learning Mobile App",'Course reports'!F2:F1005,"P2",'Course reports'!Q2:Q1005,"Fail") -> 0 | M30: =COUNTIFS('Course reports'!D2:D1005,"Reference Learning Mobile App",'Course reports'!F2:F1005,"P1",'Course reports'!Q2:Q1005,"Blocked") -> 0 | N30: =COUNTIFS('Course reports'!D2:D1005,"Reference Learning Mobile App",'Course reports'!F2:F1005,"P2",'Course reports'!Q2:Q1005,"Blocked") -> 0 | O30: =SUM(K30+M30) -> 0 | P30: =SUM(L30+N30) -> 0 | Q30: =(E30+I30)/C30 -> #DIV/0! | R30: =(F30+J30)/D30 -> 1
A31: QUML | B31: Portal | C31: =COUNTIFS(QUML!D2:D1005,"Reference Learning Web App",QUML!F2:F1005,"P1") -> 225 | D31: =COUNTIFS(QUML!D2:D1005,"Reference Learning Web App",QUML!F2:F1005,"P2") -> 192 | E31: =COUNTIFS(QUML!D2:D1005,"Reference Learning Web App",QUML!F2:F1005,"P1",QUML!R2:R1005,"NA") -> 5 | F31: =COUNTIFS(QUML!D2:D1005,"Reference Learning Web App",QUML!F2:F1005,"P2",QUML!R2:R1005,"NA") -> 4 | G31: =C31-(I31+K31+M31+E31) -> 0 | H31: =D31-(J31+L31+N31+F31) -> 0 | I31: =COUNTIFS(QUML!D2:D1005,"Reference Learning Web App",QUML!F2:F1005,"P1",QUML!R2:R1005,"Pass") -> 220 | J31: =COUNTIFS(QUML!D2:D1005,"Reference Learning Web App",QUML!F2:F1005,"P2",QUML!R2:R1005,"Pass") -> 188 | K31: =COUNTIFS(QUML!D2:D1005,"Reference Learning Web App",QUML!F2:F1005,"P1",QUML!R2:R1005,"Fail") -> 0 | L31: =COUNTIFS(QUML!D2:D1005,"Reference Learning Web App",QUML!F2:F1005,"P2",QUML!R2:R1005,"Fail") -> 0 | M31: =COUNTIFS(QUML!D2:D1005,"Reference Learning Web App",QUML!F2:F1005,"P1",QUML!R2:R1005,"Blocked") -> 0 | N31: =COUNTIFS(QUML!D2:D1005,"Reference Learning Web App",QUML!F2:F1005,"P2",QUML!R2:R1005,"Blocked") -> 0 | O31: =SUM(K31+M31) -> 0 | P31: =SUM(L31+N31) -> 0 | Q31: =(E31+I31)/C31 -> 1 | R31: =(F31+J31)/D31 -> 1
B32: Mobile | C32: =COUNTIFS(QUML!D2:D1005,"Reference Learning Mobile App",QUML!F2:F1005,"P1") -> 67 | D32: =COUNTIFS(QUML!D2:D1005,"Reference Learning Mobile App",QUML!F2:F1005,"P2") -> 59 | E32: =COUNTIFS(QUML!D2:D1005,"Reference Learning Mobile App",QUML!F2:F1005,"P1",QUML!R2:R1005,"NA") -> 0 | F32: =COUNTIFS(QUML!D2:D1005,"Reference Learning Mobile App",QUML!F2:F1005,"P2",QUML!R2:R1005,"NA") -> 1 | G32: =C32-(I32+K32+M32+E32) -> 0 | H32: =D32-(J32+L32+N32+F32) -> 0 | I32: =COUNTIFS(QUML!D2:D1005,"Reference Learning Mobile App",QUML!F2:F1005,"P1",QUML!R2:R1005,"Pass") -> 67 | J32: =COUNTIFS(QUML!D2:D1005,"Reference Learning Mobile App",QUML!F2:F1005,"P2",QUML!R2:R1005,"Pass") -> 58 | K32: =COUNTIFS(QUML!D2:D1005,"Reference Learning Mobile App",QUML!F2:F1005,"P1",QUML!R2:R1005,"Fail") -> 0 | L32: =COUNTIFS(QUML!D2:D1005,"Reference Learning Mobile App",QUML!F2:F1005,"P2",QUML!R2:R1005,"Fail") -> 0 | M32: =COUNTIFS(QUML!D2:D1005,"Reference Learning Mobile App",QUML!F2:F1005,"P1",QUML!R2:R1005,"Blocked") -> 0 | N32: =COUNTIFS(QUML!D2:D1005,"Reference Learning Mobile App",QUML!F2:F1005,"P2",QUML!R2:R1005,"Blocked") -> 0 | O32: =SUM(K32+M32) -> 0 | P32: =SUM(L32+N32) -> 0 | Q32: =(E32+I32)/C32 -> 1 | R32: =(F32+J32)/D32 -> 1
B33: Offline Desktop | C33: =COUNTIFS(QUML!D2:D1005,"Reference Learning Desktop App",QUML!F2:F1005,"P1") -> 44 | D33: =COUNTIFS(QUML!D2:D1005,"Reference Learning Desktop App",QUML!F2:F1005,"P2") -> 4 | E33: =COUNTIFS(QUML!D2:D1005,"Reference Learning Offline App",QUML!F2:F1005,"P1",QUML!R2:R1005,"NA") -> 0 | F33: =COUNTIFS(QUML!D2:D1005,"Reference Learning Offline App",QUML!F2:F1005,"P2",QUML!R2:R1005,"NA") -> 0 | G33: =C33-(I33+K33+M33+E33) -> 0 | H33: =D33-(J33+L33+N33+F33) -> 0 | I33: =COUNTIFS(QUML!D2:D1005,"Reference Learning Desktop App",QUML!F2:F1005,"P1",QUML!R2:R1005,"Pass") -> 44 | J33: =COUNTIFS(QUML!D2:D1005,"Reference Learning Desktop App",QUML!F2:F1005,"P2",QUML!R2:R1005,"Pass") -> 4 | K33: =COUNTIFS(QUML!D2:D1005,"Reference Learning Offline App",QUML!F2:F1005,"P1",QUML!R2:R1005,"Fail") -> 0 | L33: =COUNTIFS(QUML!D2:D1005,"Reference Learning Offline App",QUML!F2:F1005,"P2",QUML!R2:R1005,"Fail") -> 0 | M33: =COUNTIFS(QUML!D2:D1005,"Reference Learning Offline App",QUML!F2:F1005,"P1",QUML!R2:R1005,"Blocked") -> 0 | N33: =COUNTIFS(QUML!D2:D1005,"Reference Learning Offline App",QUML!F2:F1005,"P2",QUML!R2:R1005,"Blocked") -> 0 | O33: =SUM(K33+M33) -> 0 | P33: =SUM(L33+N33) -> 0 | Q33: =(E33+I33)/C33 -> 1 | R33: =(F33+J33)/D33 -> 1
A34: Mobile specific Test Cases | B34: Mobile | C34: =COUNTIFS('Mobile specific Test Cases'!D2:D1005,"Reference Learning Mobile App",'Mobile specific Test Cases'!F2:F1005,"P1") -> 32 | D34: =COUNTIFS('Mobile specific Test Cases'!D2:D1005,"Reference Learning Mobile App",'Mobile specific Test Cases'!F2:F1005,"P2") -> 39 | E34: =COUNTIFS('Mobile specific Test Cases'!D2:D1005,"Reference Learning Mobile App",'Mobile specific Test Cases'!F2:F1005,"P1",'Mobile specific Test Cases'!Q2:Q1005,"NA") -> 2 | F34: =COUNTIFS('Mobile specific Test Cases'!D2:D1005,"Reference Learning Mobile App",'Mobile specific Test Cases'!F2:F1005,"P2",'Mobile specific Test Cases'!Q2:Q1005,"NA") -> 0 | G34: =C34-(I34+K34+M34+E34) -> 0 | H34: =D34-(J34+L34+N34+F34) -> 0 | I34: =COUNTIFS('Mobile specific Test Cases'!D2:D1005,"Reference Learning Mobile App",'Mobile specific Test Cases'!F2:F1005,"P1",'Mobile specific Test Cases'!Q2:Q1005,"Pass") -> 30 | J34: =COUNTIFS('Mobile specific Test Cases'!D2:D1005,"Reference Learning Mobile App",'Mobile specific Test Cases'!F2:F1005,"P2",'Mobile specific Test Cases'!Q2:Q1005,"Pass") -> 39 | K34: =COUNTIFS('Mobile specific Test Cases'!D2:D1005,"Reference Learning Mobile App",'Mobile specific Test Cases'!F2:F1005,"P1",'Mobile specific Test Cases'!Q2:Q1005,"Fail") -> 0 | L34: =COUNTIFS('Mobile specific Test Cases'!D2:D1005,"Reference Learning Mobile App",'Mobile specific Test Cases'!F2:F1005,"P2",'Mobile specific Test Cases'!Q2:Q1005,"Fail") -> 0 | M34: =COUNTIFS('Mobile specific Test Cases'!D2:D1005,"Reference Learning Mobile App",'Mobile specific Test Cases'!F2:F1005,"P1",'Mobile specific Test Cases'!Q2:Q1005,"Blocked") -> 0 | N34: =COUNTIFS('Mobile specific Test Cases'!D2:D1005,"Reference Learning Mobile App",'Mobile specific Test Cases'!F2:F1005,"P2",'Mobile specific Test Cases'!Q2:Q1005,"Blocked") -> 0 | O34: =SUM(K34+M34) -> 0 | P34: =SUM(L34+N34) -> 0 | Q34: =(E34+I34)/C34 -> 1 | R34: =(F34+J34)/D34 -> 1
A35: Mobile configurability | B35: Mobile | C35: =COUNTIFS('Mobile configurability'!D2:D1005,"Reference Learning Mobile App",'Mobile configurability'!F2:F1005,"P1") -> 34 | D35: =COUNTIFS('Mobile configurability'!D2:D1005,"Reference Learning Mobile App",'Mobile configurability'!F2:F1005,"P2") -> 76 | E35: =COUNTIFS('Mobile configurability'!D2:D1005,"Reference Learning Mobile App",'Mobile configurability'!F2:F1005,"P1",'Mobile configurability'!Q2:Q1005,"NA") -> 0 | F35: =COUNTIFS('Mobile configurability'!D2:D1005,"Reference Learning Mobile App",'Mobile configurability'!F2:F1005,"P2",'Mobile configurability'!Q2:Q1005,"NA") -> 7 | G35: =C35-(I35+K35+M35+E35) -> 0 | H35: =D35-(J35+L35+N35+F35) -> 0 | I35: =COUNTIFS('Mobile configurability'!D2:D1005,"Reference Learning Mobile App",'Mobile configurability'!F2:F1005,"P1",'Mobile configurability'!Q2:Q1005,"Pass") -> 34 | J35: =COUNTIFS('Mobile configurability'!D2:D1005,"Reference Learning Mobile App",'Mobile configurability'!F2:F1005,"P2",'Mobile configurability'!Q2:Q1005,"Pass") -> 69 | K35: =COUNTIFS('Mobile configurability'!D2:D1005,"Reference Learning Mobile App",'Mobile configurability'!F2:F1005,"P1",'Mobile configurability'!Q2:Q1005,"Fail") -> 0 | L35: =COUNTIFS('Mobile configurability'!D2:D1005,"Reference Learning Mobile App",'Mobile configurability'!F2:F1005,"P2",'Mobile configurability'!Q2:Q1005,"Fail") -> 0 | M35: =COUNTIFS('Mobile configurability'!D2:D1005,"Reference Learning Mobile App",'Mobile configurability'!F2:F1005,"P1",'Mobile configurability'!Q2:Q1005,"Blocked") -> 0 | N35: =COUNTIFS('Mobile configurability'!D2:D1005,"Reference Learning Mobile App",'Mobile configurability'!F2:F1005,"P2",'Mobile configurability'!Q2:Q1005,"Blocked") -> 0 | O35: =SUM(K35+M35) -> 0 | P35: =SUM(L35+N35) -> 0 | Q35: =(E35+I35)/C35 -> 1 | R35: =(F35+J35)/D35 -> 1
A36: Org admin reports | B36: Portal | C36: =COUNTIFS('Org admin reports'!D2:D1005,"Reference Learning Web App",'Org admin reports'!F2:F1005,"P1") -> 69 | D36: =COUNTIFS('Org admin reports'!D2:D1005,"Reference Learning Web App",'Org admin reports'!F2:F1005,"P2") -> 26 | E36: =COUNTIFS('Org admin reports'!D2:D1005,"Reference Learning Web App",'Org admin reports'!F2:F1005,"P1",'Org admin reports'!Q2:Q1005,"NA") -> 5 | F36: =COUNTIFS('Org admin reports'!D2:D1005,"Reference Learning Web App",'Org admin reports'!F2:F1005,"P2",'Org admin reports'!Q2:Q1005,"NA") -> 1 | G36: =C36-(I36+K36+M36+E36) -> 0 | H36: =D36-(J36+L36+N36+F36) -> 0 | I36: =COUNTIFS('Org admin reports'!D2:D1005,"Reference Learning Web App",'Org admin reports'!F2:F1005,"P1",'Org admin reports'!Q2:Q1005,"Pass") -> 64 | J36: =COUNTIFS('Org admin reports'!D2:D1005,"Reference Learning Web App",'Org admin reports'!F2:F1005,"P2",'Org admin reports'!Q2:Q1005,"Pass") -> 25 | K36: =COUNTIFS('Org admin reports'!D2:D1005,"Reference Learning Web App",'Org admin reports'!F2:F1005,"P1",'Org admin reports'!Q2:Q1005,"Fail") -> 0 | L36: =COUNTIFS('Org admin reports'!D2:D1005,"Reference Learning Web App",'Org admin reports'!F2:F1005,"P2",'Org admin reports'!Q2:Q1005,"Fail") -> 0 | M36: =COUNTIFS('Org admin reports'!D2:D1005,"Reference Learning Web App",'Org admin reports'!F2:F1005,"P1",'Org admin reports'!Q2:Q1005,"Blocked") -> 0 | N36: =COUNTIFS('Org admin reports'!D2:D1005,"Reference Learning Web App",'Org admin reports'!F2:F1005,"P2",'Org admin reports'!Q2:Q1005,"Blocked") -> 0 | O36: =SUM(K36+M36) -> 0 | P36: =SUM(L36+N36) -> 0 | Q36: =(E36+I36)/C36 -> 1 | R36: =(F36+J36)/D36 -> 1
B37: Mobile | C37: =COUNTIFS('Org admin reports'!D2:D1005,"Reference Learning Mobile App",'Org admin reports'!F2:F1005,"P1") -> 0 | D37: =COUNTIFS('Org admin reports'!D2:D1005,"Reference Learning Mobile App",'Org admin reports'!F2:F1005,"P2") -> 5 | E37: =COUNTIFS('Org admin reports'!D2:D1005,"Reference Learning Mobile App",'Org admin reports'!F2:F1005,"P1",'Org admin reports'!Q2:Q1005,"NA") -> 0 | F37: =COUNTIFS('Org admin reports'!D2:D1005,"Reference Learning Mobile App",'Org admin reports'!F2:F1005,"P2",'Org admin reports'!Q2:Q1005,"NA") -> 0 | G37: =C37-(I37+K37+M37+E37) -> 0 | H37: =D37-(J37+L37+N37+F37) -> 0 | I37: =COUNTIFS('Org admin reports'!D2:D1005,"Reference Learning Mobile App",'Org admin reports'!F2:F1005,"P1",'Org admin reports'!Q2:Q1005,"Pass") -> 0 | J37: =COUNTIFS('Org admin reports'!D2:D1005,"Reference Learning Mobile App",'Org admin reports'!F2:F1005,"P2",'Org admin reports'!Q2:Q1005,"Pass") -> 5 | K37: =COUNTIFS('Org admin reports'!D2:D1005,"Reference Learning Mobile App",'Org admin reports'!F2:F1005,"P1",'Org admin reports'!Q2:Q1005,"Fail") -> 0 | L37: =COUNTIFS('Org admin reports'!D2:D1005,"Reference Learning Mobile App",'Org admin reports'!F2:F1005,"P2",'Org admin reports'!Q2:Q1005,"Fail") -> 0 | M37: =COUNTIFS('Org admin reports'!D2:D1005,"Reference Learning Mobile App",'Org admin reports'!F2:F1005,"P1",'Org admin reports'!Q2:Q1005,"Blocked") -> 0 | N37: =COUNTIFS('Org admin reports'!D2:D1005,"Reference Learning Mobile App",'Org admin reports'!F2:F1005,"P2",'Org admin reports'!Q2:Q1005,"Blocked") -> 0 | O37: =SUM(K37+M37) -> 0 | P37: =SUM(L37+N37) -> 0 | Q37: =(E37+I37)/C37 -> #DIV/0! | R37: =(F37+J37)/D37 -> 1
A38: QR code | B38: Portal | C38: =COUNTIFS('QR code'!D2:D1005,"Reference Learning Web App",'QR code'!F2:F1005,"P1") -> 78 | D38: =COUNTIFS('QR code'!D2:D1005,"Reference Learning Web App",'QR code'!F2:F1005,"P2") -> 18 | E38: =COUNTIFS('QR code'!D2:D1005,"Reference Learning Web App",'QR code'!F2:F1005,"P1",'QR code'!R2:R1005,"NA") -> 5 | F38: =COUNTIFS('QR code'!D2:D1005,"Reference Learning Web App",'QR code'!F2:F1005,"P2",'QR code'!R2:R1005,"NA") -> 4 | G38: =C38-(I38+K38+M38+E38) -> 0 | H38: =D38-(J38+L38+N38+F38) -> 0 | I38: =COUNTIFS('QR code'!D2:D1005,"Reference Learning Web App",'QR code'!F2:F1005,"P1",'QR code'!R2:R1005,"Pass") -> 73 | J38: =COUNTIFS('QR code'!D2:D1005,"Reference Learning Web App",'QR code'!F2:F1005,"P2",'QR code'!R2:R1005,"Pass") -> 14 | K38: =COUNTIFS('QR code'!D2:D1005,"Reference Learning Web App",'QR code'!F2:F1005,"P1",'QR code'!R2:R1005,"Fail") -> 0 | L38: =COUNTIFS('QR code'!D2:D1005,"Reference Learning Web App",'QR code'!F2:F1005,"P2",'QR code'!R2:R1005,"Fail") -> 0 | M38: =COUNTIFS('QR code'!D2:D1005,"Reference Learning Web App",'QR code'!F2:F1005,"P1",'QR code'!R2:R1005,"Blocked") -> 0 | N38: =COUNTIFS('QR code'!D2:D1005,"Reference Learning Web App",'QR code'!F2:F1005,"P2",'QR code'!R2:R1005,"Blocked") -> 0 | O38: =SUM(K38+M38) -> 0 | P38: =SUM(L38+N38) -> 0 | Q38: =(E38+I38)/C38 -> 1 | R38: =(F38+J38)/D38 -> 1
B39: Mobile | C39: =COUNTIFS('QR code'!D2:D1005,"Reference Learning Mobile App",'QR code'!F2:F1005,"P1") -> 21 | D39: =COUNTIFS('QR code'!D2:D1005,"Reference Learning Mobile App",'QR code'!F2:F1005,"P2") -> 40 | E39: =COUNTIFS('QR code'!D2:D1005,"Reference Learning Mobile App",'QR code'!F2:F1005,"P1",'QR code'!R2:R1005,"NA") -> 5 | F39: =COUNTIFS('QR code'!D2:D1005,"Reference Learning Mobile App",'QR code'!F2:F1005,"P2",'QR code'!R2:R1005,"NA") -> 5 | G39: =C39-(I39+K39+M39+E39) -> 0 | H39: =D39-(J39+L39+N39+F39) -> 0 | I39: =COUNTIFS('QR code'!D2:D1005,"Reference Learning Mobile App",'QR code'!F2:F1005,"P1",'QR code'!R2:R1005,"Pass") -> 16 | J39: =COUNTIFS('QR code'!D2:D1005,"Reference Learning Mobile App",'QR code'!F2:F1005,"P2",'QR code'!R2:R1005,"Pass") -> 35 | K39: =COUNTIFS('QR code'!D2:D1005,"Reference Learning Mobile App",'QR code'!F2:F1005,"P1",'QR code'!R2:R1005,"Fail") -> 0 | L39: =COUNTIFS('QR code'!D2:D1005,"Reference Learning Mobile App",'QR code'!F2:F1005,"P2",'QR code'!R2:R1005,"Fail") -> 0 | M39: =COUNTIFS('QR code'!D2:D1005,"Reference Learning Mobile App",'QR code'!F2:F1005,"P1",'QR code'!R2:R1005,"Blocked") -> 0 | N39: =COUNTIFS('QR code'!D2:D1005,"Reference Learning Mobile App",'QR code'!F2:F1005,"P2",'QR code'!R2:R1005,"Blocked") -> 0 | O39: =SUM(K39+M39) -> 0 | P39: =SUM(L39+N39) -> 0 | Q39: =(E39+I39)/C39 -> 1 | R39: =(F39+J39)/D39 -> 1
A40: Portal/ Desktop App Configurability | B40: Portal | C40: =COUNTIFS('Portal Desktop App Configurabil'!D2:D1005,"Reference Learning Web App",'Portal Desktop App Configurabil'!F2:F1005,"P1") -> 36 | D40: =COUNTIFS('Portal Desktop App Configurabil'!D2:D1005,"Reference Learning Web App",'Portal Desktop App Configurabil'!F2:F1005,"P2") -> 25 | E40: =COUNTIFS('Portal Desktop App Configurabil'!D2:D1005,"Reference Learning Web App",'Portal Desktop App Configurabil'!F2:F1005,"P1",'Portal Desktop App Configurabil'!Q2:Q1005,"NA") -> 2 | F40: =COUNTIFS('Portal Desktop App Configurabil'!D2:D1005,"Reference Learning Web App",'Portal Desktop App Configurabil'!F2:F1005,"P2",'Portal Desktop App Configurabil'!Q2:Q1005,"NA") -> 1 | G40: =C40-(I40+K40+M40+E40) -> 0 | H40: =D40-(J40+L40+N40+F40) -> 0 | I40: =COUNTIFS('Portal Desktop App Configurabil'!D2:D1005,"Reference Learning Web App",'Portal Desktop App Configurabil'!F2:F1005,"P1",'Portal Desktop App Configurabil'!Q2:Q1005,"Pass") -> 34 | J40: =COUNTIFS('Portal Desktop App Configurabil'!D2:D1005,"Reference Learning Web App",'Portal Desktop App Configurabil'!F2:F1005,"P2",'Portal Desktop App Configurabil'!Q2:Q1005,"Pass") -> 24 | K40: =COUNTIFS('Portal Desktop App Configurabil'!D2:D1005,"Reference Learning Web App",'Portal Desktop App Configurabil'!F2:F1005,"P1",'Portal Desktop App Configurabil'!Q2:Q1005,"Fail") -> 0 | L40: =COUNTIFS('Portal Desktop App Configurabil'!D2:D1005,"Reference Learning Web App",'Portal Desktop App Configurabil'!F2:F1005,"P2",'Portal Desktop App Configurabil'!Q2:Q1005,"Fail") -> 0 | M40: =COUNTIFS('Portal Desktop App Configurabil'!D2:D1005,"Reference Learning Web App",'Portal Desktop App Configurabil'!F2:F1005,"P1",'Portal Desktop App Configurabil'!Q2:Q1005,"Blocked") -> 0 | N40: =COUNTIFS('Portal Desktop App Configurabil'!D2:D1005,"Reference Learning Web App",'Portal Desktop App Configurabil'!F2:F1005,"P2",'Portal Desktop App Configurabil'!Q2:Q1005,"Blocked") -> 0 | O40: =SUM(K40+M40) -> 0 | P40: =SUM(L40+N40) -> 0 | Q40: =(E40+I40)/C40 -> 1 | R40: =(F40+J40)/D40 -> 1
...

Sheet Sunbird ED Execution Dashboard
A1: Sunbird ED Regression Dashboard
A2: ED Component | B2: Portal/Mobile/Desktop app | C2: Total | E2: Not Applicable | G2: To be Executed | I2: Passed | K2: Fail | M2: Blocked | O2: For retest (Failed & Blocked) | Q2: Execution % circle wise
C3: P1 | D3: P2 | E3: P1 | F3: P2 | G3: P1 | H3: P2 | I3: P1 | J3: P2 | K3: P1 | L3: P2 | M3: P1 | N3: P2 | O3: P1 | P3: P2 | Q3: P1 | R3: P2
A4: Sanity | B4: Portal | C4: =COUNTA('Portal Sanity'!D2:D1005) -> 110 | D4: 0 | E4: =COUNTIF('Portal Sanity'!K2:K1005,"NA") -> 2 | F4: 0 | G4: =C4-(I4+O4+E4) -> 0 | H4: 0 | I4: =COUNTIF('Portal Sanity'!K2:K1005,"Pass") -> 108 | J4: 0 | K4: =COUNTIF('Portal Sanity'!K2:K1005,"Fail") -> 0 | L4: 0 | M4: =COUNTIF('Portal Sanity'!K2:K1005,"Blocked") -> 0 | N4: 0 | O4: =SUM(K4+M4) -> 0 | P4: 0 | Q4: =(E4+I4)/C4 -> 1 | R4: 0
B5: Mobile | C5: =COUNTA('Mobile Sanity'!D2:D1005) -> 111 | D5: 0 | E5: =COUNTIF('Mobile Sanity'!K2:K1005,"NA") -> 4 | F5: 0 | G5: =C5-(I5+O5+E5) -> 0 | H5: 0 | I5: =COUNTIF('Mobile Sanity'!K2:K1005,"Pass") -> 107 | J5: 0 | K5: =COUNTIF('Mobile Sanity'!K2:K1005,"Fail") -> 0 | L5: 0 | M5: =COUNTIF('Mobile Sanity'!K2:K1005,"Blocked") -> 0 | N5: 0 | O5: =SUM(K5+M5) -> 0 | P5: 0 | Q5: =(E5+I5)/C5 -> 1 | R5: 0
B6: Desktop | C6: =COUNTA('Desktop Sanity'!D2:D1005) -> 53 | D6: 0 | E6: =COUNTIF('Desktop Sanity'!K2:K1005,"NA") -> 6 | F6: 0 | G6: =C6-(I6+O6+E6) -> 0 | H6: 0 | I6: =COUNTIF('Desktop Sanity'!K2:K1005,"Pass") -> 47 | J6: 0 | K6: =COUNTIF('Desktop Sanity'!K2:K1005,"Fail") -> 0 | L6: 0 | M6: =COUNTIF('Desktop Sanity'!K2:K1005,"Blocked") -> 0 | N6: 0 | O6: =SUM(K6+M6) -> 0 | P6: 0 | Q6: =(E6+I6)/C6 -> 1 | R6: 0
A7: Sanity New Framework | B7: Portal | C7: =COUNTA('Portal Sanity'!D2:D1005) -> 110 | D7: 0 | E7: =COUNTIF('Portal Sanity'!O2:O1005,"NA") -> 1 | F7: 0 | G7: =C7-(I7+O7+E7) -> 0 | H7: 0 | I7: =COUNTIF('Portal Sanity'!O2:O1005,"Pass") -> 109 | J7: 0 | K7: =COUNTIF('Portal Sanity'!O2:O1005,"Fail") -> 0 | L7: 0 | M7: =COUNTIF('Portal Sanity'!O2:O1005,"Blocked") -> 0 | N7: 0 | O7: =SUM(K7+M7) -> 0 | P7: 0 | Q7: =(E7+I7)/C7 -> 1 | R7: 0
B8: Mobile | C8: =COUNTA('Mobile Sanity'!D2:D1005) -> 111 | D8: 0 | E8: =COUNTIF('Mobile Sanity'!O2:O1005,"NA") -> 5 | F8: 0 | G8: =C8-(I8+O8+E8) -> 0 | H8: 0 | I8: =COUNTIF('Mobile Sanity'!O2:O1005,"Pass") -> 106 | J8: 0 | K8: =COUNTIF('Mobile Sanity'!O2:O1005,"Fail") -> 0 | L8: 0 | M8: =COUNTIF('Mobile Sanity'!O2:O1005,"Blocked") -> 0 | N8: 0 | O8: =SUM(K8+M8) -> 0 | P8: 0 | Q8: =(E8+I8)/C8 -> 1 | R8: 0
B9: Desktop | C9: =COUNTA('Desktop Sanity'!D2:D1005) -> 53 | D9: 0 | E9: =COUNTIF('Desktop Sanity'!O2:O1005,"NA") -> 6 | F9: 0 | G9: =C9-(I9+O9+E9) -> 0 | H9: 0 | I9: =COUNTIF('Desktop Sanity'!O2:O1005,"Pass") -> 47 | J9: 0 | K9: =COUNTIF('Desktop Sanity'!O2:O1005,"Fail") -> 0 | L9: 0 | M9: =COUNTIF('Desktop Sanity'!O2:O1005,"Blocked") -> 0 | N9: 0 | O9: =SUM(K9+M9) -> 0 | P9: 0 | Q9: =(E9+I9)/C9 -> 1 | R9: 0
A10: 7.0.0 New Feature S1 Defects | B10: Portal/Mobile/Offline Desktop | C10: =COUNTA('7.0.0 New Feature S1 Defects'!B2:B1005) -> 45 | D10: 0 | E10: =COUNTIF('7.0.0 New Feature S1 Defects'!E2:E1005,"NA") -> 1 | F10: 0 | G10: =C10-(I10+O10+E10) -> 0 | H10: 0 | I10: =COUNTIF('7.0.0 New Feature S1 Defects'!E2:E1005,"Pass") -> 44 | J10: 0 | K10: =COUNTIF('7.0.0 New Feature S1 Defects'!E2:E1005,"Fail") -> 0 | L10: 0 | M10: =COUNTIF('7.0.0 New Feature S1 Defects'!E2:E1005,"Blocked") -> 0 | N10: 0 | O10: =SUM(K10+M10) -> 0 | P10: 0 | Q10: =(E10+I10)/C10 -> 1 | R10: 0
A11: 6.0.0 OCI S1 Defects | B11: Portal/Mobile/Offline Desktop | C11: =COUNTA('6.0.0 OCI S1 Defects'!B2:B1005) -> 46 | D11: 0 | E11: =COUNTIF('6.0.0 OCI S1 Defects'!E2:E1005,"NA") -> 1 | F11: 0 | G11: =C11-(I11+O11+E11) -> 0 | H11: 0 | I11: =COUNTIF('6.0.0 OCI S1 Defects'!E2:E1005,"Pass") -> 45 | J11: 0 | K11: =COUNTIF('6.0.0 OCI S1 Defects'!E2:E1005,"Fail") -> 0 | L11: 0 | M11: =COUNTIF('6.0.0 OCI S1 Defects'!E2:E1005,"Blocked") -> 0 | N11: 0 | O11: =SUM(K11+M11) -> 0 | P11: 0 | Q11: =(E11+I11)/C11 -> 1 | R11: 0
A12: WorkSpace | B12: Portal | C12: =COUNTIF(Workspace!F2:F1005,"P1") -> 264 | D12: =COUNTIF(Workspace!F2:F1005,"P2") -> 327 | E12: =COUNTIFS(Workspace!F2:F1005,"P1",Workspace!T2:T1005,"NA") -> 14 | F12: =COUNTIFS(Workspace!F2:F1005,"P2",Workspace!T2:T1005,"NA") -> 26 | G12: =C12-(I12+K12+M12+E12) -> 0 | H12: =D12-(J12+L12+N12+F12) -> 0 | I12: =COUNTIFS(Workspace!F2:F1005,"P1",Workspace!T2:T1005,"Pass") -> 250 | J12: =COUNTIFS(Workspace!F2:F1005,"P2",Workspace!T2:T1005,"Pass") -> 301 | K12: =COUNTIFS(Workspace!F2:F1005,"P1",Workspace!T2:T1005,"Fail") -> 0 | L12: =COUNTIFS(Workspace!F2:F1005,"P2",Workspace!T2:T1005,"Fail") -> 0 | M12: =COUNTIFS(Workspace!F2:F1005,"P1",Workspace!T2:T1005,"Blocked") -> 0 | N12: =COUNTIFS(Workspace!F2:F1005,"P2",Workspace!T2:T1005,"Blocked") -> 0 | O12: =SUM(K12+M12) -> 0 | P12: =SUM(L12+N12) -> 0 | Q12: =(E12+I12)/C12 -> 1 | R12: =(F12+J12)/D12 -> 1
A13: Login | B13: Portal | C13: =COUNTIFS(Login!D2:D1005,"Reference Learning Web App",Login!F2:F1005,"P1") -> 61 | D13: =COUNTIFS(Login!D2:D1005,"Reference Learning Web App",Login!F2:F1005,"P2") -> 73 | E13: =COUNTIFS(Login!D2:D1005,"Reference Learning Web App",Login!F2:F1005,"P1",Login!R2:R1005,"NA") -> 2 | F13: =COUNTIFS(Login!D2:D1005,"Reference Learning Web App",Login!F2:F1005,"P2",Login!R2:R1005,"NA") -> 5 | G13: =C13-(I13+K13+M13+E13) -> 0 | H13: =D13-(J13+L13+N13+F13) -> 0 | I13: =COUNTIFS(Login!D2:D1005,"Reference Learning Web App",Login!F2:F1005,"P1",Login!R2:R1005,"Pass") -> 59 | J13: =COUNTIFS(Login!D2:D1005,"Reference Learning Web App",Login!F2:F1005,"P2",Login!R2:R1005,"Pass") -> 68 | K13: =COUNTIFS(Login!D2:D1005,"Reference Learning Web App",Login!F2:F1005,"P1",Login!R2:R1005,"Fail") -> 0 | L13: =COUNTIFS(Login!D2:D1005,"Reference Learning Web App",Login!F2:F1005,"P2",Login!R2:R1005,"Fail") -> 0 | M13: =COUNTIFS(Login!D2:D1005,"Reference Learning Web App",Login!F2:F1005,"P1",Login!R2:R1005,"Blocked") -> 0 | N13: =COUNTIFS(Login!D2:D1005,"Reference Learning Web App",Login!F2:F1005,"P2",Login!R2:R1005,"Blocked") -> 0 | O13: =SUM(K13+M13) -> 0 | P13: =SUM(L13+N13) -> 0 | Q13: =(E13+I13)/C13 -> 1 | R13: =(F13+J13)/D13 -> 1
B14: Mobile | C14: =COUNTIFS(Login!D2:D1005,"Reference Learning Mobile App",Login!F2:F1005,"P1") -> 62 | D14: =COUNTIFS(Login!D2:D1005,"Reference Learning Mobile App",Login!F2:F1005,"P2") -> 87 | E14: =COUNTIFS(Login!D2:D1005,"Reference Learning Mobile App",Login!F2:F1005,"P1",Login!R2:R1005,"NA") -> 1 | F14: =COUNTIFS(Login!D2:D1005,"Reference Learning Mobile App",Login!F2:F1005,"P2",Login!R2:R1005,"NA") -> 4 | G14: =C14-(I14+K14+M14+E14) -> 0 | H14: =D14-(J14+L14+N14+F14) -> 0 | I14: =COUNTIFS(Login!D2:D1005,"Reference Learning Mobile App",Login!F2:F1005,"P1",Login!R2:R1005,"Pass") -> 61 | J14: =COUNTIFS(Login!D2:D1005,"Reference Learning Mobile App",Login!F2:F1005,"P2",Login!R2:R1005,"Pass") -> 83 | K14: =COUNTIFS(Login!D2:D1005,"Reference Learning Mobile App",Login!F2:F1005,"P1",Login!R2:R1005,"Fail") -> 0 | L14: =COUNTIFS(Login!D2:D1005,"Reference Learning Mobile App",Login!F2:F1005,"P2",Login!R2:R1005,"Fail") -> 0 | M14: =COUNTIFS(Login!D2:D1005,"Reference Learning Mobile App",Login!F2:F1005,"P1",Login!R2:R1005,"Blocked") -> 0 | N14: =COUNTIFS(Login!D2:D1005,"Reference Learning Mobile App",Login!F2:F1005,"P2",Login!R2:R1005,"Blocked") -> 0 | O14: =SUM(K14+M14) -> 0 | P14: =SUM(L14+N14) -> 0 | Q14: =(E14+I14)/C14 -> 1 | R14: =(F14+J14)/D14 -> 1
B15: Offline Desktop | C15: =COUNTIFS(Login!D2:D1005,"Reference Learning Desktop App",Login!F2:F1005,"P1") -> 22 | D15: =COUNTIFS(Login!D2:D1005,"Reference Learning Desktop App",Login!F2:F1005,"P2") -> 26 | E15: =COUNTIFS(Login!D2:D1005,"Reference Learning Desktop App",Login!F2:F1005,"P1",Login!R2:R1005,"NA") -> 0 | F15: =COUNTIFS(Login!D2:D1005,"Reference Learning Desktop App",Login!F2:F1005,"P2",Login!R2:R1005,"NA") -> 0 | G15: =C15-(I15+K15+M15+E15) -> 0 | H15: =D15-(J15+L15+N15+F15) -> 0 | I15: =COUNTIFS(Login!D2:D1005,"Reference Learning Desktop App",Login!F2:F1005,"P1",Login!R2:R1005,"Pass") -> 22 | J15: =COUNTIFS(Login!D2:D1005,"Reference Learning Desktop App",Login!F2:F1005,"P2",Login!R2:R1005,"Pass") -> 26 | K15: =COUNTIFS(Login!D2:D1005,"Reference Learning Desktop App",Login!F2:F1005,"P1",Login!R2:R1005,"Fail") -> 0 | L15: =COUNTIFS(Login!D2:D1005,"Reference Learning Desktop App",Login!F2:F1005,"P2",Login!R2:R1005,"Fail") -> 0 | M15: =COUNTIFS(Login!D2:D1005,"Reference Learning Desktop App",Login!F2:F1005,"P1",Login!R2:R1005,"Blocked") -> 0 | N15: =COUNTIFS(Login!D2:D1005,"Reference Learning Desktop App",Login!F2:F1005,"P2",Login!R2:R1005,"Blocked") -> 0 | O15: =SUM(K15+M15) -> 0 | P15: =SUM(L15+N15) -> 0 | Q15: =(E15+I15)/C15 -> 1 | R15: =(F15+J15)/D15 -> 1
A16: Course Consumption | B16: Portal | C16: =COUNTIFS('Course Consumption'!D2:D1005,"Reference Learning Web App",'Course Consumption'!F2:F1005,"P1") -> 163 | D16: =COUNTIFS('Course Consumption'!D2:D1005,"Reference Learning Web App",'Course Consumption'!F2:F1005,"P2") -> 59 | E16: =COUNTIFS('Course Consumption'!D2:D1005,"Reference Learning Web App",'Course Consumption'!F2:F1005,"P1",'Course Consumption'!R2:R1005,"NA") -> 8 | F16: =COUNTIFS('Course Consumption'!D2:D1005,"Reference Learning Web App",'Course Consumption'!F2:F1005,"P2",'Course Consumption'!R2:R1005,"NA") -> 1 | G16: =C16-(I16+K16+M16+E16) -> 0 | H16: =D16-(J16+L16+N16+F16) -> 0 | I16: =COUNTIFS('Course Consumption'!D2:D1005,"Reference Learning Web App",'Course Consumption'!F2:F1005,"P1",'Course Consumption'!R2:R1005,"Pass") -> 155 | J16: =COUNTIFS('Course Consumption'!D2:D1005,"Reference Learning Web App",'Course Consumption'!F2:F1005,"P2",'Course Consumption'!R2:R1005,"Pass") -> 58 | K16: =COUNTIFS('Course Consumption'!D2:D1005,"Reference Learning Web App",'Course Consumption'!F2:F1005,"P1",'Course Consumption'!R2:R1005,"Fail") -> 0 | L16: =COUNTIFS('Course Consumption'!D2:D1005,"Reference Learning Web App",'Course Consumption'!F2:F1005,"P2",'Course Consumption'!R2:R1005,"Fail") -> 0 | M16: =COUNTIFS('Course Consumption'!D2:D1005,"Reference Learning Web App",'Course Consumption'!F2:F1005,"P1",'Course Consumption'!R2:R1005,"Blocked") -> 0 | N16: =COUNTIFS('Course Consumption'!D2:D1005,"Reference Learning Web App",'Course Consumption'!F2:F1005,"P2",'Course Consumption'!R2:R1005,"Blocked") -> 0 | O16: =SUM(K16+M16) -> 0 | P16: =SUM(L16+N16) -> 0 | Q16: =(E16+I16)/C16 -> 1 | R16: =(F16+J16)/D16 -> 1
